<mujoco model="example">
    <compiler angle="radian" meshdir="meshes" autolimits="true" />
    <option timestep="0.01" gravity="0 0 -9.81" integrator="implicitfast" />
    <asset>
        <texture type="skybox" file="/home/albusgive/CPP_space/mujoco_test/desert.png"
            gridsize="3 4" gridlayout=".U..LFRB.D.." />
        <texture name="plane" type="2d" builtin="checker" rgb1=".1 .1 .1" rgb2=".9 .9 .9"
            width="512" height="512" mark="cross" markrgb=".8 .8 .8" />
        <material name="plane" reflectance="0.3" texture="plane" texrepeat="1 1" texuniform="true" />
    </asset>
    <visual>
        <!-- 质量 -->
        <quality shadowsize="16384" numslices="28" offsamples="4" />
        <headlight diffuse="1 1 1" specular="0.5 0.5 0.5" active="0" />
    </visual>

    <worldbody>
        <light directional="true" pos="0 0 30" dir="0 -0.5 -1" />
        <geom name="floor" pos="0 0 0" size="0 0 .25" type="plane" material="plane"
            condim="3" />
        <!-- <geom type="box" size="0.3 0.3 0.5"/> -->

        <body name="base_body" pos="0 0 1">
            <freejoint />
            <geom type="box" size="0.5 0.5 0.01" rgba="0.5 0.5 0.5 1" mass="15" />

            <body name="Mecanum_A1" pos="0.5 0.6 0" euler="1.5707963267948966 0 0">
                <joint name="a1" type="hinge" pos="0 0 0" axis="0 0 1" frictionloss=".000002" />
                <geom type="cylinder" size="0.05 0.1" rgba=".1 .1 .1 1" />
                <site type="cylinder" size="0.15 0.045" rgba=".5 .1 .1 .5" />
                <replicate count="16" euler="0 0 0.3925">
                    <body euler="-0.78539815 0 0">
                        <joint type="hinge" pos="0.15 0 0" axis="0 0 1" frictionloss=".000002" />
                        <geom type="capsule" size="0.015 0.05" pos="0.15 0 0" />
                    </body>
                </replicate>
            </body>

            <body name="Mecanum_B1" pos="-0.5 0.6 0" euler="1.5707963267948966 0 0">
                <joint name="b1" type="hinge" pos="0 0 0" axis="0 0 1" frictionloss=".000002" />
                <geom type="cylinder" size="0.05 0.1" rgba=".1 .1 .1 1" />
                <site type="cylinder" size="0.15 0.045" rgba=".1 .1 .5 .5" />
                <replicate count="16" euler="0 0 0.3925">
                    <body euler="0.78539815 0 0">
                        <joint type="hinge" pos="0.15 0 0" axis="0 0 1" frictionloss=".000002" />
                        <geom type="capsule" size="0.015 0.05" pos="0.15 0 0" />
                    </body>
                </replicate>
            </body>

            <body name="Mecanum_A2" pos="-0.5 -0.6 0" euler="1.5707963267948966 0 0">
                <joint name="a2" type="hinge" pos="0 0 0" axis="0 0 1" frictionloss=".000002" />
                <geom type="cylinder" size="0.05 0.1" rgba=".1 .1 .1 1" />
                <site type="cylinder" size="0.15 0.045" rgba=".5 .1 .1 .5" />
                <replicate count="16" euler="0 0 0.3925">
                    <body euler="-0.78539815 0 0">
                        <joint type="hinge" pos="0.15 0 0" axis="0 0 1" frictionloss=".000002" />
                        <geom type="capsule" size="0.015 0.05" pos="0.15 0 0" />
                    </body>
                </replicate>
            </body>

            <body name="Mecanum_B2" pos="0.5 -0.6 0" euler="1.5707963267948966 0 0">
                <joint name="b2" type="hinge" pos="0 0 0" axis="0 0 1" frictionloss=".000002" />
                <geom type="cylinder" size="0.05 0.1" rgba=".1 .1 .1 1" />
                <site type="cylinder" size="0.15 0.045" rgba=".1 .1 .5 .5" />
                <replicate count="16" euler="0 0 0.3925">
                    <body euler="0.78539815 0 0">
                        <joint type="hinge" pos="0.15 0 0" axis="0 0 1" frictionloss=".000002" />
                        <geom type="capsule" size="0.015 0.05" pos="0.15 0 0" />
                    </body>
                </replicate>
            </body>
        </body>

    </worldbody>
    <tendon>
        <fixed name="forward">
            <joint joint="a1" coef="0.25" />
            <joint joint="b1" coef="0.25" />
            <joint joint="a2" coef="0.25" />
            <joint joint="b2" coef="0.25" />
        </fixed>
        <fixed name="transverse" frictionloss="0.001">
            <joint joint="a1" coef=".25" />
            <joint joint="b1" coef="-0.25" />
            <joint joint="a2" coef=".25" />
            <joint joint="b2" coef="-0.25" />
        </fixed>
        <fixed name="roatate">
            <joint joint="a1" coef=".25" />
            <joint joint="b1" coef=".25" />
            <joint joint="a2" coef="-.25" />
            <joint joint="b2" coef="-.25" />
        </fixed>
    </tendon>
    <actuator>
        <velocity tendon="forward" name="forward" kv="30" ctrlrange="-15 15"/>
        <velocity tendon="transverse" name="transverse" kv="30" ctrlrange="-15 15"/>
        <velocity tendon="roatate" name="roatate" kv="30" ctrlrange="-15 15"/>
    </actuator>
</mujoco>