<?xml version="1.0" encoding="utf-8"?>
<mujoco model="inverted_pendulum">
    <compiler angle="radian" meshdir="meshes" autolimits="true" />
    <option timestep="0.002" gravity="0 0 -9.81" integrator="implicitfast" density="1.225"
        viscosity="1.8e-5" />

    <visual>
        <quality shadowsize="16384" numslices="28" offsamples="4" />
        <headlight diffuse="1 1 1" specular="0.5 0.5 0.5" active="1" />
    </visual>
    <asset>
        <mesh name="tetrahedron" vertex="0 0 0 1 0 0 0 1 0 0 0 1" />
        <texture type="skybox" file="../asset/desert.png"
            gridsize="3 4" gridlayout=".U..LFRB.D.." />
        <texture name="plane" type="2d" builtin="checker" rgb1=".1 .1 .1" rgb2=".9 .9 .9"
            width="512" height="512" mark="cross" markrgb=".8 .8 .8" />
        <material name="plane" reflectance="0.3" texture="plane" texrepeat="1 1" texuniform="true" />
    </asset>

    <worldbody>
        <geom name="floor" pos="0 0 0" size="0 0 .25" type="plane" material="plane"
            condim="3" />
        <light directional="true" ambient=".3 .3 .3" pos="30 30 30" dir="0 -.5 -1"
            diffuse=".5 .5 .5" specular=".5 .5 .5" />

        <body name="B" pos="0 0 0">
            <freejoint />
            <site name="imu" />
            <camera name="cam2armor1" mode="track" fovy="54.225" />
            <geom type="box" size="0.1 0.1 0.1" />
        </body>

        <body pos="0 0 1">
            <geom type="box" size=".3 .3 .005" rgba=".2 .2 .2 1" />
            <body name="up_box" pos="0 0 .02">
                <site name="force_torque" />
                <geom type="box" size=".3 .3 .005" rgba=".3 .3 1 1" mass="0.01"/>
            </body>
        </body>


        <!-- 支撑柱 -->
        <body name="support" pos="1 0 0.1">
            <geom type="cylinder" mass="100" size="0.05 0.5" rgba="0.2 0.2 0.2 1" />
            <!-- 水平杆 -->
            <body name="rotay_am" pos="0 0 0.51">
                <joint type="hinge" name="pivot" pos="0 0 0" axis="0 0 1" damping="0.001"
                    frictionloss="0.0" stiffness="0.5" />
                <geom type="capsule" mass="0.01" fromto="0 0 0 0.2 0 0" size="0.01"
                    rgba="0.8 0.2 0.2 0.5" />
                <!-- 摆 -->
                <body name="pendulum" pos="0.2 0 0">
                    <joint type="hinge" name="ph" pos="0 0 0" axis="1 0 0" damping="0.001"
                        frictionloss="0.0" />
                    <geom type="capsule" mass="0.005" fromto="0 0 0 0 0 -0.3" size="0.01"
                        rgba="0.8 0.2 0.2 1" />
                    <!-- 配重 -->
                    <geom type="sphere" mass="0.01" size="0.03" pos="0 0 -0.3" rgba="0.2 0.8 0.2 1" />
                </body>
            </body>
        </body>

    </worldbody>
    <sensor>
        <framequat name='orientation' objtype='site' objname='imu' />
        <subtreelinvel name="base_lin_vel" body="B" />
        <gyro name='base_ang_vel' site='imu' />
        <framepos name='base_pos' objtype='body' objname='B' />

        <force name="force" site="force_torque" />
        <torque name="torque" site="force_torque" />

        <jointpos name='pivot_p' joint='pivot' />
        <jointvel name='pivot_v' joint='pivot' />
    </sensor>

    <actuator>
        <position kp="2" kv="0.1" name="pivot" joint="pivot" ctrlrange="-3.14 3.14"
            forcerange="-5 5" />
    </actuator>
</mujoco>