<?xml version="1.0" encoding="utf-8"?>
<mujoco model="inverted_pendulum">
    <compiler angle="radian" meshdir="meshes" autolimits="true" />
    <option timestep="0.002" gravity="0 0 -9.81" wind="0 0 0" integrator="implicitfast"
        density="1.225"
        viscosity="1.8e-5" />

    <visual>
        <global realtime="1" />
        <quality shadowsize="16384" numslices="28" offsamples="4" />
        <headlight diffuse="1 1 1" specular="0.5 0.5 0.5" active="1" />
        <rgba fog="1 0 0 1" haze="1 1 1 1" />
    </visual>

    <asset>
        <texture type="skybox" file="../asset/desert.png"
            gridsize="3 4" gridlayout=".U..LFRB.D.." />
        <texture name="plane" type="2d" builtin="checker" rgb1=".1 .1 .1" rgb2=".9 .9 .9"
            width="512" height="512" mark="cross" markrgb=".8 .8 .8" />
        <material name="plane" reflectance="0.3" texture="plane" texrepeat="1 1" texuniform="true" />
        <material name="box" rgba="0 0.5 0 1" emission="0" />
    </asset>

    <default>
        <geom solref=".5e-4" solimp="0.9 0.99 1e-4" fluidcoef="0.5 0.25 0.5 2.0 1.0" />
        <default class="card">
            <geom type="mesh" mesh="card" mass="1.84e-4" fluidshape="ellipsoid" contype="0"
                conaffinity="0" />
        </default>
        <default class="collision">
            <geom type="box" mass="0" size="0.047 0.032 .00035" group="3" friction=".1" />
        </default>
    </default>

    <worldbody>
        <geom name="floor" pos="0 0 0" size="10 10 .1" type="plane" material="plane"
            condim="3" />
        <light directional="true" ambient=".3 .3 .3" pos="30 30 30" dir="0 -2 -1"
            diffuse=".5 .5 .5" specular=".5 .5 .5" />

        <!-- 支撑柱 -->
        <body name="support" pos="0 0 0.1">
            <geom type="cylinder" mass="100" size="0.05 0.5" rgba="0.2 0.2 0.2 1"/>
            <!-- 水平杆 -->
            <body name="rotay_am" pos="0 0 0.51">
                <joint type="hinge" name="pivot" pos="0 0 0" axis="0 0 1" damping="0.001"
                    frictionloss="0.0" />
                <geom type="capsule" mass="0.01" fromto="0 0 0 0.2 0 0" size="0.01"
                    rgba="0.8 0.2 0.2 0.5"/>
                <!-- 摆 -->
                <body name="pendulum" pos="0.2 0 0">
                    <joint type="hinge" name="ph" pos="0 0 0" axis="1 0 0" damping="0.001"
                        frictionloss="0.0" />
                    <geom type="capsule" mass="0.005" fromto="0 0 0 0 0 -0.3" size="0.01"
                        rgba="0.8 0.2 0.2 1" />
                    <!-- 配重 -->
                    <geom type="sphere" mass="0.01" size="0.03" pos="0 0 -0.3" rgba="0.2 0.8 0.2 1" />
                </body>
            </body>
        </body>

    </worldbody>
</mujoco>