<?xml version="1.0" encoding="utf-8"?>
<mujoco model="">
    <compiler angle="degree" autolimits="true" />
    <option timestep="0.002" gravity="0 0 -9.81" wind="0 0 0" integrator="implicitfast"
        density="1.225"
        viscosity="1.8e-5" />

    <visual>
        <global realtime="1" />
        <quality shadowsize="16384" offsamples="32" numslices="40" numstacks="32" numquads="8" />
        <headlight diffuse=".5 .5 .5" specular=".1 .1 .1" active="0" />
        <rgba fog="1 0 0 1" haze="1 1 0.878431373 1" />
    </visual>

    <asset>
        <texture type="cube" file="./iron_block.png" />
        <material name="iron_block" texture="iron_block" />
        <texture type="cube" file="./carved_pumpkin.png" />
        <material name="carved_pumpkin" texture="carved_pumpkin" />
        <texture type="cube" file="./pumpkin_side.png" />
        <material name="pumpkin_side" texture="pumpkin_side" />
        <texture type="cube" file="./pumpkin_top.png" />
        <material name="pumpkin_top" texture="pumpkin_top" />

        <texture type="skybox" file="../../MJCF/asset/desert.png"
            gridsize="3 4" gridlayout=".U..LFRB.D.." />
        <texture type="skybox" builtin="flat" rgb1="1 1 .1" rgb2=".9 .9 .9" width="128"
            height="128" />

        <texture name="plane" type="2d" builtin="checker" rgb1=".1 .1 .1" rgb2=".9 .9 .9"
            width="512" height="512" mark="cross" markrgb=".8 .8 .8" />
        <texture type="2d" file="./sea.png" />
        <material name="plane" reflectance="0.3" texture="sea" texrepeat="1 1" texuniform="true" />
    </asset>

    <worldbody>
        <geom name="floor" pos="0 0 0" size="0 0 .25" type="plane" material="plane"
            condim="3" />

        <body name="iron_golem" pos="0 0 0.5" axisangle="0 0 1 180">
            <light pos="0 1 3" dir="10 0 -1" ambient="1 1 1" cutoff="30" exponent="0"
                mode="targetbody" target="iron_golem" diffuse=".5 .5 .5" specular=" 1 1 1" />
            <light pos="0 -1 3" dir="10 0 -1" ambient="1 1 1" cutoff="30" exponent="0"
                mode="targetbody" target="iron_golem" diffuse=".5 .5 .5" specular=" 1 1 1" />

            <camera pos="0 2 .5" mode="targetbody" target="iron_golem" />
            <camera pos="2 1 .5" mode="targetbody" target="iron_golem" />
            <camera pos="-2 1 .5" mode="targetbody" target="iron_golem" />
            <camera pos="0 -2 .5" mode="targetbody" target="iron_golem" />

            <camera pos="0 0 2" mode="targetbody" target="iron_golem" />
            <camera pos="-2 -2 2" mode="targetbody" target="iron_golem" />
            <camera pos="2 2 2" mode="targetbody" target="iron_golem" />
            <camera pos="2 -2 2" mode="targetbody" target="iron_golem" />

            <camera pos="0 1 .5" mode="targetbody" target="iron_golem" />
            <camera pos="0 1.2 .5" mode="targetbody" target="iron_golem" />
            <camera pos="0 1.6 .5" mode="targetbody" target="iron_golem" />
            <camera pos="0 2 .5" mode="targetbody" target="iron_golem" />
            <camera pos="0 2.5 .5" mode="targetbody" target="iron_golem" />
            <camera pos="0 3 .5" mode="targetbody" target="iron_golem" />
            <camera pos="0 4 .5" mode="targetbody" target="iron_golem" />

            <joint name="body_run" type="slide" axis="0 1 0" />
            <geom name="pumpkin_top" type="box" size="0.0999 0.0999 0.0001" pos="0 0 0.1"
                material="pumpkin_top" />
            <geom name="carved_pumpkin" type="box" size="0.0999 0.0001 0.0999" pos="0 0.1 0"
                axisangle="0 1 0 180" material="carved_pumpkin" />
            <geom type="box" size="0.1 0.1 0.1" axisangle="1 0 0 90" material="pumpkin_side" />
            <body pos="0 0 -0.4">
                <joint name="body_jnt" type="slide" axis="0 1 0" range="-0.1 0.1" />

                <geom type="box" size="0.1 0.1 0.1" pos="0.2 0 0.2" material="iron_block" mass="0.1" />
                <geom type="box" size="0.1 0.1 0.1" pos="-0.2 0 0.2" material="iron_block"
                    mass="0.1" />
            </body>
            <body pos="0 0 -0.4">
                <joint name="arm_jnt" type="slide" axis="0 1 0" range="-0.1 0.1" />
                <geom type="box" size="0.1 0.1 0.1" pos="0 0 0.2" material="iron_block" contype="0"
                    conaffinity="0" mass="0.1" />
                <geom type="box" size="0.1 0.1 0.1" material="iron_block" contype="0"
                    conaffinity="0" mass="0.1" />
            </body>
        </body>

    </worldbody>
    <actuator>
        <!-- <position joint="body_jnt" kp="10" kv="01" />
        <position joint="arm_jnt" kp="10" kv="01" /> -->
        <!-- <motor joint="body_jnt" />
        <motor joint="arm_jnt" /> -->
        <velocity joint="body_jnt" kv="10" />
        <velocity joint="arm_jnt" kv="10" />
        <motor joint="body_run" />
    </actuator>
</mujoco>
