<mujoco>
    <compiler angle="radian" meshdir="meshes" autolimits="true" />
    <asset>
        <mesh name="tetrahedron" vertex="0 0 0 1 0 0 0 1 0 0 0 1" />
        <texture type="skybox" file="../asset/desert.png"
            gridsize="3 4" gridlayout=".U..LFRB.D.." />
        <texture name="plane" type="2d" builtin="checker" rgb1=".1 .1 .1" rgb2=".9 .9 .9"
            width="512" height="512" mark="cross" markrgb=".8 .8 .8" />
        <material name="plane" reflectance="0.3" texture="plane" texrepeat="1 1" texuniform="true" />
    </asset>

    <worldbody>
        <geom name="floor" pos="0 0 0" size="0 0 .25" type="plane" material="plane"
            condim="3" />
        <light directional="true" ambient=".3 .3 .3" pos="30 30 30" dir="0 -.5 -1"
            diffuse=".5 .5 .5" specular=".5 .5 .5" />

        <body pos="0 0 0" mocap="true">
            <geom type="cylinder" mass="100" size="0.05 0.5" rgba=".2 .2 .2 1" />
            <body pos="0 0 0.51">
                <joint type="hinge" name="pivot" pos="0 0 0" axis="0 0 1" damping="0"
                    frictionloss="0.0" stiffness="0" />
                <geom type="capsule" mass="0.01" fromto="0 0 0 0.2 0 0" size="0.01"
                    rgba="0.8 0.2 0.2 0.5" />
            </body>
        </body>

        <body pos="0 0 1.5">
            <site name="ceiling" pos="0 0 .15" />
            <geom type="sphere" size="0.15" rgba="0 0 0 0.5"/>
            <body pos="0 0 0">
                <joint name="joint1" type="hinge" axis="0 1 0" range="-1.3 1.57"/>
                <site name="hook1" type="sphere" size="0.03" pos="0.5 0 0.03" rgba="0 1 0 1" />
                <geom type="capsule" size="0.05" fromto="0 0 0 .6 0 0" rgba=".5 .5 .5 .5"/>
            </body>
        </body>

    </worldbody>

    <tendon>
        <spatial name="A" springlength="0 0.5" stiffness="10" damping="10" width="0.01" rgba="1 0 0 1">
            <site site="ceiling" />
            <site site="hook1" />
        </spatial>
    </tendon>

    <actuator>
        <motor name="joint" joint="pivot"/>
        <muscle name="A" tendon="A" ctrlrange="-.5 .5"/>
    </actuator>

    <keyframe>
        <key qpos="0.03 0" mpos="0 0 .5"/>
        <key qpos="0.06 0" />
        <key qpos="0.09 0" />
    </keyframe>
    <!-- <include file="key.xml"/> -->
</mujoco>